  | Name  | Type                       | Params
-----------------------------------------------------
0 | model | T5ForConditionalGeneration | 222 M
-----------------------------------------------------
222 M     Trainable params
0         Non-trainable params
222 M     Total params
891.614   Total estimated model params size (MB)
Traceback (most recent call last):
  File "/home/dnaihao/anaconda3/envs/442/lib/python3.7/site-packages/pytorch_lightning/utilities/parsing.py", line 182, in __getattr__
    return self[key]
KeyError: 'data_dir'
The above exception was the direct cause of the following exception:
Traceback (most recent call last):
  File "main.py", line 22, in <module>
    main()
  File "main.py", line 18, in main
    T5_train(args)
  File "/home/dnaihao/In-the-wild-QA/src/T5/train.py", line 57, in T5_train
    trainer.fit(model)
  File "/home/dnaihao/anaconda3/envs/442/lib/python3.7/site-packages/pytorch_lightning/trainer/trainer.py", line 513, in fit
    self.dispatch()
  File "/home/dnaihao/anaconda3/envs/442/lib/python3.7/site-packages/pytorch_lightning/trainer/trainer.py", line 553, in dispatch
    self.accelerator.start_training(self)
  File "/home/dnaihao/anaconda3/envs/442/lib/python3.7/site-packages/pytorch_lightning/accelerators/accelerator.py", line 74, in start_training
    self.training_type_plugin.start_training(trainer)
  File "/home/dnaihao/anaconda3/envs/442/lib/python3.7/site-packages/pytorch_lightning/plugins/training_type/training_type_plugin.py", line 111, in start_training
    self._results = trainer.run_train()
  File "/home/dnaihao/anaconda3/envs/442/lib/python3.7/site-packages/pytorch_lightning/trainer/trainer.py", line 614, in run_train
    self.run_sanity_check(self.lightning_module)
  File "/home/dnaihao/anaconda3/envs/442/lib/python3.7/site-packages/pytorch_lightning/trainer/trainer.py", line 853, in run_sanity_check
    self.reset_val_dataloader(ref_model)
  File "/home/dnaihao/anaconda3/envs/442/lib/python3.7/site-packages/pytorch_lightning/trainer/data_loading.py", line 364, in reset_val_dataloader
    self.num_val_batches, self.val_dataloaders = self._reset_eval_dataloader(model, 'val')
  File "/home/dnaihao/anaconda3/envs/442/lib/python3.7/site-packages/pytorch_lightning/trainer/data_loading.py", line 278, in _reset_eval_dataloader
    dataloaders = self.request_dataloader(getattr(model, loader_name))
  File "/home/dnaihao/anaconda3/envs/442/lib/python3.7/site-packages/pytorch_lightning/trainer/data_loading.py", line 398, in request_dataloader
    dataloader = dataloader_fx()
  File "/home/dnaihao/In-the-wild-QA/src/T5/model.py", line 149, in val_dataloader
    val_dataset = get_dataset(tokenizer=self.tokenizer, type_path="dev", args=self.hparams)
  File "/home/dnaihao/In-the-wild-QA/src/T5/T5_dataloader.py", line 6, in get_dataset
    return T5Dataset(tokenizer=tokenizer, data_dir=args.data_dir, type_path=type_path, max_len=args.max_seq_length)
  File "/home/dnaihao/anaconda3/envs/442/lib/python3.7/site-packages/pytorch_lightning/utilities/parsing.py", line 184, in __getattr__
    raise AttributeError(f'Missing attribute "{key}"') from exp
AttributeError: Missing attribute "data_dir"